2017-06-06 15:35:03 base.py[line:131] ERROR Job "update_task_list (trigger: interval[0:00:05], next run at: 2017-06-06 15:35:07 CST)" raised an exception
Traceback (most recent call last):
  File "/Library/Frameworks/Python.framework/Versions/3.5/lib/python3.5/site-packages/apscheduler/executors/base.py", line 125, in run_job
    retval = job.func(*job.args, **job.kwargs)
  File "/Users/cn/Desktop/apscheduler_delay/apscheduler_client/client_doc/request_server.py", line 181, in update_task_list
    obj.update_task_list()
  File "/Users/cn/Desktop/apscheduler_delay/apscheduler_client/client_doc/request_server.py", line 91, in update_task_list
    True
  File "/Library/Frameworks/Python.framework/Versions/3.5/lib/python3.5/site-packages/pymongo/collection.py", line 2503, in update
    collation=collation)
  File "/Library/Frameworks/Python.framework/Versions/3.5/lib/python3.5/site-packages/pymongo/collection.py", line 754, in _update
    _check_write_command_response([(0, result)])
  File "/Library/Frameworks/Python.framework/Versions/3.5/lib/python3.5/site-packages/pymongo/helpers.py", line 315, in _check_write_command_response
    raise WriteError(error.get("errmsg"), error.get("code"), error)
pymongo.errors.WriteError: The _id field cannot be changed from {_id: "59365a6bde9df072b7713906"} to {_id: "59365b25de9df072b7715810"}.
